{
 "cells": [
  {
   "cell_type": "code",
   "execution_count": 6,
   "metadata": {},
   "outputs": [],
   "source": [
    "import sys\n",
    "sys.path.insert(0, \"./../\")\n",
    "\n",
    "import os\n",
    "import utils_modelling as utils"
   ]
  },
  {
   "cell_type": "code",
   "execution_count": 4,
   "metadata": {},
   "outputs": [],
   "source": [
    "path_dataset = \"./../../../dataset_used_split_v2\"\n",
    "path_train = os.path.join(path_dataset, \"train\")\n",
    "path_val = os.path.join(path_dataset, \"val\")\n",
    "path_test = os.path.join(path_dataset, \"test\")"
   ]
  },
  {
   "cell_type": "code",
   "execution_count": 7,
   "metadata": {},
   "outputs": [
    {
     "name": "stdout",
     "output_type": "stream",
     "text": [
      "Found 247 files belonging to 1 classes.\n",
      "Found 247 files belonging to 1 classes.\n",
      "Found 36 files belonging to 1 classes.\n",
      "Found 36 files belonging to 1 classes.\n",
      "Found 71 files belonging to 1 classes.\n",
      "Found 71 files belonging to 1 classes.\n"
     ]
    }
   ],
   "source": [
    "trainset = utils.prepare_data(\n",
    "    os.path.join(path_train, \"fundus_image\"),\n",
    "    os.path.join(path_train, \"mask_image\")\n",
    ")\n",
    "valset = utils.prepare_data(\n",
    "    os.path.join(path_val, \"fundus_image\"),\n",
    "    os.path.join(path_val, \"mask_image\")\n",
    ")\n",
    "testset = utils.prepare_data(\n",
    "    os.path.join(path_test, \"fundus_image\"),\n",
    "    os.path.join(path_test, \"mask_image\")\n",
    ")"
   ]
  },
  {
   "cell_type": "code",
   "execution_count": 35,
   "metadata": {},
   "outputs": [],
   "source": [
    "import tensorflow as tf\n",
    "\n",
    "def load_check_img(file_path):\n",
    "    try:\n",
    "        img=tf.io.read_file(file_path)\n",
    "        img=tf.image.decode_jpeg(img, channels=3)\n",
    "    except Exception as e:\n",
    "        print(e, file_path, \"error\", sep=\" \")"
   ]
  },
  {
   "cell_type": "code",
   "execution_count": 12,
   "metadata": {},
   "outputs": [],
   "source": [
    "train_img = os.path.join(path_train, \"fundus_image\")\n",
    "train_mask = os.path.join(path_train, \"mask_image\")\n",
    "val_img = os.path.join(path_val, \"fundus_image\")\n",
    "val_mask = os.path.join(path_val, \"mask_image\")\n",
    "test_img = os.path.join(path_test, \"fundus_image\")\n",
    "test_mask = os.path.join(path_test, \"mask_image\")"
   ]
  },
  {
   "cell_type": "code",
   "execution_count": 19,
   "metadata": {},
   "outputs": [],
   "source": [
    "train_img_files = tf.data.Dataset.list_files(train_img + \"/*.jpg\")"
   ]
  },
  {
   "cell_type": "code",
   "execution_count": 36,
   "metadata": {},
   "outputs": [
    {
     "name": "stdout",
     "output_type": "stream",
     "text": [
      "{{function_node __wrapped__DecodeJpeg_device_/job:localhost/replica:0/task:0/device:CPU:0}} jpeg::Uncompress failed. Invalid JPEG data or crop window. [Op:DecodeJpeg] ./../../../dataset_used_split_v2\\train\\fundus_image\\fff_0_122451_l_1.jpg error\n"
     ]
    }
   ],
   "source": [
    "for file in os.listdir(train_img):\n",
    "    load_check_img(os.path.join(train_img, file))"
   ]
  },
  {
   "cell_type": "code",
   "execution_count": 8,
   "metadata": {},
   "outputs": [],
   "source": [
    "unet_custom = utils.custom_unet()"
   ]
  },
  {
   "cell_type": "code",
   "execution_count": 9,
   "metadata": {},
   "outputs": [],
   "source": [
    "unet_custom.compile(optimizer=\"adam\",\n",
    "                    loss=\"sparse_categorical_crossentropy\",\n",
    "                    metrics=[\"accuracy\"])"
   ]
  },
  {
   "cell_type": "code",
   "execution_count": 10,
   "metadata": {},
   "outputs": [
    {
     "name": "stdout",
     "output_type": "stream",
     "text": [
      "Epoch 1/10\n"
     ]
    },
    {
     "ename": "InvalidArgumentError",
     "evalue": "Graph execution error:\n\n2 root error(s) found.\n  (0) INVALID_ARGUMENT:  jpeg::Uncompress failed. Invalid JPEG data or crop window.\n\t [[{{node decode_image/DecodeImage}}]]\n\t [[IteratorGetNext]]\n\t [[Shape/_10]]\n  (1) INVALID_ARGUMENT:  jpeg::Uncompress failed. Invalid JPEG data or crop window.\n\t [[{{node decode_image/DecodeImage}}]]\n\t [[IteratorGetNext]]\n0 successful operations.\n0 derived errors ignored. [Op:__inference_train_function_2006]",
     "output_type": "error",
     "traceback": [
      "\u001b[1;31m---------------------------------------------------------------------------\u001b[0m",
      "\u001b[1;31mInvalidArgumentError\u001b[0m                      Traceback (most recent call last)",
      "Cell \u001b[1;32mIn[10], line 1\u001b[0m\n\u001b[1;32m----> 1\u001b[0m \u001b[43munet_custom\u001b[49m\u001b[38;5;241;43m.\u001b[39;49m\u001b[43mfit\u001b[49m\u001b[43m(\u001b[49m\u001b[43mtrainset\u001b[49m\u001b[43m,\u001b[49m\n\u001b[0;32m      2\u001b[0m \u001b[43m                \u001b[49m\u001b[43mvalidation_data\u001b[49m\u001b[38;5;241;43m=\u001b[39;49m\u001b[43mvalset\u001b[49m\u001b[43m,\u001b[49m\n\u001b[0;32m      3\u001b[0m \u001b[43m                \u001b[49m\u001b[43mepochs\u001b[49m\u001b[38;5;241;43m=\u001b[39;49m\u001b[38;5;241;43m10\u001b[39;49m\u001b[43m)\u001b[49m\n",
      "File \u001b[1;32mc:\\Users\\Bugi\\miniconda3\\envs\\modeling\\lib\\site-packages\\keras\\utils\\traceback_utils.py:70\u001b[0m, in \u001b[0;36mfilter_traceback.<locals>.error_handler\u001b[1;34m(*args, **kwargs)\u001b[0m\n\u001b[0;32m     67\u001b[0m     filtered_tb \u001b[38;5;241m=\u001b[39m _process_traceback_frames(e\u001b[38;5;241m.\u001b[39m__traceback__)\n\u001b[0;32m     68\u001b[0m     \u001b[38;5;66;03m# To get the full stack trace, call:\u001b[39;00m\n\u001b[0;32m     69\u001b[0m     \u001b[38;5;66;03m# `tf.debugging.disable_traceback_filtering()`\u001b[39;00m\n\u001b[1;32m---> 70\u001b[0m     \u001b[38;5;28;01mraise\u001b[39;00m e\u001b[38;5;241m.\u001b[39mwith_traceback(filtered_tb) \u001b[38;5;28;01mfrom\u001b[39;00m \u001b[38;5;28;01mNone\u001b[39;00m\n\u001b[0;32m     71\u001b[0m \u001b[38;5;28;01mfinally\u001b[39;00m:\n\u001b[0;32m     72\u001b[0m     \u001b[38;5;28;01mdel\u001b[39;00m filtered_tb\n",
      "File \u001b[1;32mc:\\Users\\Bugi\\miniconda3\\envs\\modeling\\lib\\site-packages\\tensorflow\\python\\eager\\execute.py:54\u001b[0m, in \u001b[0;36mquick_execute\u001b[1;34m(op_name, num_outputs, inputs, attrs, ctx, name)\u001b[0m\n\u001b[0;32m     52\u001b[0m \u001b[38;5;28;01mtry\u001b[39;00m:\n\u001b[0;32m     53\u001b[0m   ctx\u001b[38;5;241m.\u001b[39mensure_initialized()\n\u001b[1;32m---> 54\u001b[0m   tensors \u001b[38;5;241m=\u001b[39m pywrap_tfe\u001b[38;5;241m.\u001b[39mTFE_Py_Execute(ctx\u001b[38;5;241m.\u001b[39m_handle, device_name, op_name,\n\u001b[0;32m     55\u001b[0m                                       inputs, attrs, num_outputs)\n\u001b[0;32m     56\u001b[0m \u001b[38;5;28;01mexcept\u001b[39;00m core\u001b[38;5;241m.\u001b[39m_NotOkStatusException \u001b[38;5;28;01mas\u001b[39;00m e:\n\u001b[0;32m     57\u001b[0m   \u001b[38;5;28;01mif\u001b[39;00m name \u001b[38;5;129;01mis\u001b[39;00m \u001b[38;5;129;01mnot\u001b[39;00m \u001b[38;5;28;01mNone\u001b[39;00m:\n",
      "\u001b[1;31mInvalidArgumentError\u001b[0m: Graph execution error:\n\n2 root error(s) found.\n  (0) INVALID_ARGUMENT:  jpeg::Uncompress failed. Invalid JPEG data or crop window.\n\t [[{{node decode_image/DecodeImage}}]]\n\t [[IteratorGetNext]]\n\t [[Shape/_10]]\n  (1) INVALID_ARGUMENT:  jpeg::Uncompress failed. Invalid JPEG data or crop window.\n\t [[{{node decode_image/DecodeImage}}]]\n\t [[IteratorGetNext]]\n0 successful operations.\n0 derived errors ignored. [Op:__inference_train_function_2006]"
     ]
    }
   ],
   "source": [
    "unet_custom.fit(trainset,\n",
    "                validation_data=valset,\n",
    "                epochs=10)"
   ]
  },
  {
   "cell_type": "markdown",
   "metadata": {},
   "source": [
    "### checkpoint"
   ]
  },
  {
   "cell_type": "code",
   "execution_count": 3,
   "metadata": {},
   "outputs": [],
   "source": [
    "train_img, train_mask = utils.load_img_mask(path_train)\n",
    "val_img, val_mask = utils.load_img_mask(path_val)\n",
    "test_img, test_mask = utils.load_img_mask(path_test)"
   ]
  },
  {
   "cell_type": "code",
   "execution_count": 4,
   "metadata": {},
   "outputs": [],
   "source": [
    "trainset = utils.create_dataset(train_img, train_mask)\n",
    "valset = utils.create_dataset(val_img, val_mask)\n",
    "testset = utils.create_dataset(test_img, test_mask)"
   ]
  },
  {
   "cell_type": "code",
   "execution_count": 5,
   "metadata": {},
   "outputs": [],
   "source": [
    "unet_custom = utils.custom_unet()"
   ]
  },
  {
   "cell_type": "code",
   "execution_count": 6,
   "metadata": {},
   "outputs": [],
   "source": [
    "unet_custom.compile(optimizer=\"adam\",\n",
    "                    loss=\"sparse_categorical_crossentropy\",\n",
    "                    metrics=[\"accuracy\"])"
   ]
  },
  {
   "cell_type": "code",
   "execution_count": 7,
   "metadata": {},
   "outputs": [
    {
     "name": "stdout",
     "output_type": "stream",
     "text": [
      "Epoch 1/10\n"
     ]
    },
    {
     "ename": "NotFoundError",
     "evalue": "Graph execution error:\n\nDetected at node 'gradient_tape/model/conv2d_10/Conv2D/Conv2DBackpropInput' defined at (most recent call last):\n    File \"c:\\Users\\Bugi\\miniconda3\\envs\\modeling\\lib\\runpy.py\", line 196, in _run_module_as_main\n      return _run_code(code, main_globals, None,\n    File \"c:\\Users\\Bugi\\miniconda3\\envs\\modeling\\lib\\runpy.py\", line 86, in _run_code\n      exec(code, run_globals)\n    File \"c:\\Users\\Bugi\\miniconda3\\envs\\modeling\\lib\\site-packages\\ipykernel_launcher.py\", line 18, in <module>\n      app.launch_new_instance()\n    File \"c:\\Users\\Bugi\\miniconda3\\envs\\modeling\\lib\\site-packages\\traitlets\\config\\application.py\", line 1075, in launch_instance\n      app.start()\n    File \"c:\\Users\\Bugi\\miniconda3\\envs\\modeling\\lib\\site-packages\\ipykernel\\kernelapp.py\", line 739, in start\n      self.io_loop.start()\n    File \"c:\\Users\\Bugi\\miniconda3\\envs\\modeling\\lib\\site-packages\\tornado\\platform\\asyncio.py\", line 205, in start\n      self.asyncio_loop.run_forever()\n    File \"c:\\Users\\Bugi\\miniconda3\\envs\\modeling\\lib\\asyncio\\base_events.py\", line 603, in run_forever\n      self._run_once()\n    File \"c:\\Users\\Bugi\\miniconda3\\envs\\modeling\\lib\\asyncio\\base_events.py\", line 1909, in _run_once\n      handle._run()\n    File \"c:\\Users\\Bugi\\miniconda3\\envs\\modeling\\lib\\asyncio\\events.py\", line 80, in _run\n      self._context.run(self._callback, *self._args)\n    File \"c:\\Users\\Bugi\\miniconda3\\envs\\modeling\\lib\\site-packages\\ipykernel\\kernelbase.py\", line 545, in dispatch_queue\n      await self.process_one()\n    File \"c:\\Users\\Bugi\\miniconda3\\envs\\modeling\\lib\\site-packages\\ipykernel\\kernelbase.py\", line 534, in process_one\n      await dispatch(*args)\n    File \"c:\\Users\\Bugi\\miniconda3\\envs\\modeling\\lib\\site-packages\\ipykernel\\kernelbase.py\", line 437, in dispatch_shell\n      await result\n    File \"c:\\Users\\Bugi\\miniconda3\\envs\\modeling\\lib\\site-packages\\ipykernel\\ipkernel.py\", line 362, in execute_request\n      await super().execute_request(stream, ident, parent)\n    File \"c:\\Users\\Bugi\\miniconda3\\envs\\modeling\\lib\\site-packages\\ipykernel\\kernelbase.py\", line 778, in execute_request\n      reply_content = await reply_content\n    File \"c:\\Users\\Bugi\\miniconda3\\envs\\modeling\\lib\\site-packages\\ipykernel\\ipkernel.py\", line 449, in do_execute\n      res = shell.run_cell(\n    File \"c:\\Users\\Bugi\\miniconda3\\envs\\modeling\\lib\\site-packages\\ipykernel\\zmqshell.py\", line 549, in run_cell\n      return super().run_cell(*args, **kwargs)\n    File \"c:\\Users\\Bugi\\miniconda3\\envs\\modeling\\lib\\site-packages\\IPython\\core\\interactiveshell.py\", line 3075, in run_cell\n      result = self._run_cell(\n    File \"c:\\Users\\Bugi\\miniconda3\\envs\\modeling\\lib\\site-packages\\IPython\\core\\interactiveshell.py\", line 3130, in _run_cell\n      result = runner(coro)\n    File \"c:\\Users\\Bugi\\miniconda3\\envs\\modeling\\lib\\site-packages\\IPython\\core\\async_helpers.py\", line 128, in _pseudo_sync_runner\n      coro.send(None)\n    File \"c:\\Users\\Bugi\\miniconda3\\envs\\modeling\\lib\\site-packages\\IPython\\core\\interactiveshell.py\", line 3334, in run_cell_async\n      has_raised = await self.run_ast_nodes(code_ast.body, cell_name,\n    File \"c:\\Users\\Bugi\\miniconda3\\envs\\modeling\\lib\\site-packages\\IPython\\core\\interactiveshell.py\", line 3517, in run_ast_nodes\n      if await self.run_code(code, result, async_=asy):\n    File \"c:\\Users\\Bugi\\miniconda3\\envs\\modeling\\lib\\site-packages\\IPython\\core\\interactiveshell.py\", line 3577, in run_code\n      exec(code_obj, self.user_global_ns, self.user_ns)\n    File \"C:\\Users\\Bugi\\AppData\\Local\\Temp\\ipykernel_20844\\2650939347.py\", line 1, in <module>\n      unet_custom.fit(trainset,\n    File \"c:\\Users\\Bugi\\miniconda3\\envs\\modeling\\lib\\site-packages\\keras\\utils\\traceback_utils.py\", line 65, in error_handler\n      return fn(*args, **kwargs)\n    File \"c:\\Users\\Bugi\\miniconda3\\envs\\modeling\\lib\\site-packages\\keras\\engine\\training.py\", line 1564, in fit\n      tmp_logs = self.train_function(iterator)\n    File \"c:\\Users\\Bugi\\miniconda3\\envs\\modeling\\lib\\site-packages\\keras\\engine\\training.py\", line 1160, in train_function\n      return step_function(self, iterator)\n    File \"c:\\Users\\Bugi\\miniconda3\\envs\\modeling\\lib\\site-packages\\keras\\engine\\training.py\", line 1146, in step_function\n      outputs = model.distribute_strategy.run(run_step, args=(data,))\n    File \"c:\\Users\\Bugi\\miniconda3\\envs\\modeling\\lib\\site-packages\\keras\\engine\\training.py\", line 1135, in run_step\n      outputs = model.train_step(data)\n    File \"c:\\Users\\Bugi\\miniconda3\\envs\\modeling\\lib\\site-packages\\keras\\engine\\training.py\", line 997, in train_step\n      self.optimizer.minimize(loss, self.trainable_variables, tape=tape)\n    File \"c:\\Users\\Bugi\\miniconda3\\envs\\modeling\\lib\\site-packages\\keras\\optimizers\\optimizer_v2\\optimizer_v2.py\", line 576, in minimize\n      grads_and_vars = self._compute_gradients(\n    File \"c:\\Users\\Bugi\\miniconda3\\envs\\modeling\\lib\\site-packages\\keras\\optimizers\\optimizer_v2\\optimizer_v2.py\", line 634, in _compute_gradients\n      grads_and_vars = self._get_gradients(\n    File \"c:\\Users\\Bugi\\miniconda3\\envs\\modeling\\lib\\site-packages\\keras\\optimizers\\optimizer_v2\\optimizer_v2.py\", line 510, in _get_gradients\n      grads = tape.gradient(loss, var_list, grad_loss)\nNode: 'gradient_tape/model/conv2d_10/Conv2D/Conv2DBackpropInput'\nNo algorithm worked!  Error messages:\n  Profiling failure on CUDNN engine 1#TC: RESOURCE_EXHAUSTED: Out of memory while trying to allocate 151096336 bytes.\n  Profiling failure on CUDNN engine 1: RESOURCE_EXHAUSTED: Out of memory while trying to allocate 151096336 bytes.\n  Profiling failure on CUDNN engine 2#TC: RESOURCE_EXHAUSTED: Out of memory while trying to allocate 289407744 bytes.\n  Profiling failure on CUDNN engine 2: RESOURCE_EXHAUSTED: Out of memory while trying to allocate 289407744 bytes.\n  Profiling failure on CUDNN engine 3#TC: RESOURCE_EXHAUSTED: Out of memory while trying to allocate 91448832 bytes.\n  Profiling failure on CUDNN engine 3: RESOURCE_EXHAUSTED: Out of memory while trying to allocate 91448832 bytes.\n  Profiling failure on CUDNN engine 0#TC: RESOURCE_EXHAUSTED: Out of memory while trying to allocate 16777216 bytes.\n  Profiling failure on CUDNN engine 0: RESOURCE_EXHAUSTED: Out of memory while trying to allocate 16777216 bytes.\n\t [[{{node gradient_tape/model/conv2d_10/Conv2D/Conv2DBackpropInput}}]] [Op:__inference_train_function_1632]",
     "output_type": "error",
     "traceback": [
      "\u001b[1;31m---------------------------------------------------------------------------\u001b[0m",
      "\u001b[1;31mNotFoundError\u001b[0m                             Traceback (most recent call last)",
      "Cell \u001b[1;32mIn[7], line 1\u001b[0m\n\u001b[1;32m----> 1\u001b[0m \u001b[43munet_custom\u001b[49m\u001b[38;5;241;43m.\u001b[39;49m\u001b[43mfit\u001b[49m\u001b[43m(\u001b[49m\u001b[43mtrainset\u001b[49m\u001b[43m,\u001b[49m\n\u001b[0;32m      2\u001b[0m \u001b[43m                \u001b[49m\u001b[43mvalidation_data\u001b[49m\u001b[38;5;241;43m=\u001b[39;49m\u001b[43mvalset\u001b[49m\u001b[43m,\u001b[49m\n\u001b[0;32m      3\u001b[0m \u001b[43m                \u001b[49m\u001b[43mepochs\u001b[49m\u001b[38;5;241;43m=\u001b[39;49m\u001b[38;5;241;43m10\u001b[39;49m\u001b[43m)\u001b[49m\n",
      "File \u001b[1;32mc:\\Users\\Bugi\\miniconda3\\envs\\modeling\\lib\\site-packages\\keras\\utils\\traceback_utils.py:70\u001b[0m, in \u001b[0;36mfilter_traceback.<locals>.error_handler\u001b[1;34m(*args, **kwargs)\u001b[0m\n\u001b[0;32m     67\u001b[0m     filtered_tb \u001b[38;5;241m=\u001b[39m _process_traceback_frames(e\u001b[38;5;241m.\u001b[39m__traceback__)\n\u001b[0;32m     68\u001b[0m     \u001b[38;5;66;03m# To get the full stack trace, call:\u001b[39;00m\n\u001b[0;32m     69\u001b[0m     \u001b[38;5;66;03m# `tf.debugging.disable_traceback_filtering()`\u001b[39;00m\n\u001b[1;32m---> 70\u001b[0m     \u001b[38;5;28;01mraise\u001b[39;00m e\u001b[38;5;241m.\u001b[39mwith_traceback(filtered_tb) \u001b[38;5;28;01mfrom\u001b[39;00m \u001b[38;5;28;01mNone\u001b[39;00m\n\u001b[0;32m     71\u001b[0m \u001b[38;5;28;01mfinally\u001b[39;00m:\n\u001b[0;32m     72\u001b[0m     \u001b[38;5;28;01mdel\u001b[39;00m filtered_tb\n",
      "File \u001b[1;32mc:\\Users\\Bugi\\miniconda3\\envs\\modeling\\lib\\site-packages\\tensorflow\\python\\eager\\execute.py:54\u001b[0m, in \u001b[0;36mquick_execute\u001b[1;34m(op_name, num_outputs, inputs, attrs, ctx, name)\u001b[0m\n\u001b[0;32m     52\u001b[0m \u001b[38;5;28;01mtry\u001b[39;00m:\n\u001b[0;32m     53\u001b[0m   ctx\u001b[38;5;241m.\u001b[39mensure_initialized()\n\u001b[1;32m---> 54\u001b[0m   tensors \u001b[38;5;241m=\u001b[39m pywrap_tfe\u001b[38;5;241m.\u001b[39mTFE_Py_Execute(ctx\u001b[38;5;241m.\u001b[39m_handle, device_name, op_name,\n\u001b[0;32m     55\u001b[0m                                       inputs, attrs, num_outputs)\n\u001b[0;32m     56\u001b[0m \u001b[38;5;28;01mexcept\u001b[39;00m core\u001b[38;5;241m.\u001b[39m_NotOkStatusException \u001b[38;5;28;01mas\u001b[39;00m e:\n\u001b[0;32m     57\u001b[0m   \u001b[38;5;28;01mif\u001b[39;00m name \u001b[38;5;129;01mis\u001b[39;00m \u001b[38;5;129;01mnot\u001b[39;00m \u001b[38;5;28;01mNone\u001b[39;00m:\n",
      "\u001b[1;31mNotFoundError\u001b[0m: Graph execution error:\n\nDetected at node 'gradient_tape/model/conv2d_10/Conv2D/Conv2DBackpropInput' defined at (most recent call last):\n    File \"c:\\Users\\Bugi\\miniconda3\\envs\\modeling\\lib\\runpy.py\", line 196, in _run_module_as_main\n      return _run_code(code, main_globals, None,\n    File \"c:\\Users\\Bugi\\miniconda3\\envs\\modeling\\lib\\runpy.py\", line 86, in _run_code\n      exec(code, run_globals)\n    File \"c:\\Users\\Bugi\\miniconda3\\envs\\modeling\\lib\\site-packages\\ipykernel_launcher.py\", line 18, in <module>\n      app.launch_new_instance()\n    File \"c:\\Users\\Bugi\\miniconda3\\envs\\modeling\\lib\\site-packages\\traitlets\\config\\application.py\", line 1075, in launch_instance\n      app.start()\n    File \"c:\\Users\\Bugi\\miniconda3\\envs\\modeling\\lib\\site-packages\\ipykernel\\kernelapp.py\", line 739, in start\n      self.io_loop.start()\n    File \"c:\\Users\\Bugi\\miniconda3\\envs\\modeling\\lib\\site-packages\\tornado\\platform\\asyncio.py\", line 205, in start\n      self.asyncio_loop.run_forever()\n    File \"c:\\Users\\Bugi\\miniconda3\\envs\\modeling\\lib\\asyncio\\base_events.py\", line 603, in run_forever\n      self._run_once()\n    File \"c:\\Users\\Bugi\\miniconda3\\envs\\modeling\\lib\\asyncio\\base_events.py\", line 1909, in _run_once\n      handle._run()\n    File \"c:\\Users\\Bugi\\miniconda3\\envs\\modeling\\lib\\asyncio\\events.py\", line 80, in _run\n      self._context.run(self._callback, *self._args)\n    File \"c:\\Users\\Bugi\\miniconda3\\envs\\modeling\\lib\\site-packages\\ipykernel\\kernelbase.py\", line 545, in dispatch_queue\n      await self.process_one()\n    File \"c:\\Users\\Bugi\\miniconda3\\envs\\modeling\\lib\\site-packages\\ipykernel\\kernelbase.py\", line 534, in process_one\n      await dispatch(*args)\n    File \"c:\\Users\\Bugi\\miniconda3\\envs\\modeling\\lib\\site-packages\\ipykernel\\kernelbase.py\", line 437, in dispatch_shell\n      await result\n    File \"c:\\Users\\Bugi\\miniconda3\\envs\\modeling\\lib\\site-packages\\ipykernel\\ipkernel.py\", line 362, in execute_request\n      await super().execute_request(stream, ident, parent)\n    File \"c:\\Users\\Bugi\\miniconda3\\envs\\modeling\\lib\\site-packages\\ipykernel\\kernelbase.py\", line 778, in execute_request\n      reply_content = await reply_content\n    File \"c:\\Users\\Bugi\\miniconda3\\envs\\modeling\\lib\\site-packages\\ipykernel\\ipkernel.py\", line 449, in do_execute\n      res = shell.run_cell(\n    File \"c:\\Users\\Bugi\\miniconda3\\envs\\modeling\\lib\\site-packages\\ipykernel\\zmqshell.py\", line 549, in run_cell\n      return super().run_cell(*args, **kwargs)\n    File \"c:\\Users\\Bugi\\miniconda3\\envs\\modeling\\lib\\site-packages\\IPython\\core\\interactiveshell.py\", line 3075, in run_cell\n      result = self._run_cell(\n    File \"c:\\Users\\Bugi\\miniconda3\\envs\\modeling\\lib\\site-packages\\IPython\\core\\interactiveshell.py\", line 3130, in _run_cell\n      result = runner(coro)\n    File \"c:\\Users\\Bugi\\miniconda3\\envs\\modeling\\lib\\site-packages\\IPython\\core\\async_helpers.py\", line 128, in _pseudo_sync_runner\n      coro.send(None)\n    File \"c:\\Users\\Bugi\\miniconda3\\envs\\modeling\\lib\\site-packages\\IPython\\core\\interactiveshell.py\", line 3334, in run_cell_async\n      has_raised = await self.run_ast_nodes(code_ast.body, cell_name,\n    File \"c:\\Users\\Bugi\\miniconda3\\envs\\modeling\\lib\\site-packages\\IPython\\core\\interactiveshell.py\", line 3517, in run_ast_nodes\n      if await self.run_code(code, result, async_=asy):\n    File \"c:\\Users\\Bugi\\miniconda3\\envs\\modeling\\lib\\site-packages\\IPython\\core\\interactiveshell.py\", line 3577, in run_code\n      exec(code_obj, self.user_global_ns, self.user_ns)\n    File \"C:\\Users\\Bugi\\AppData\\Local\\Temp\\ipykernel_20844\\2650939347.py\", line 1, in <module>\n      unet_custom.fit(trainset,\n    File \"c:\\Users\\Bugi\\miniconda3\\envs\\modeling\\lib\\site-packages\\keras\\utils\\traceback_utils.py\", line 65, in error_handler\n      return fn(*args, **kwargs)\n    File \"c:\\Users\\Bugi\\miniconda3\\envs\\modeling\\lib\\site-packages\\keras\\engine\\training.py\", line 1564, in fit\n      tmp_logs = self.train_function(iterator)\n    File \"c:\\Users\\Bugi\\miniconda3\\envs\\modeling\\lib\\site-packages\\keras\\engine\\training.py\", line 1160, in train_function\n      return step_function(self, iterator)\n    File \"c:\\Users\\Bugi\\miniconda3\\envs\\modeling\\lib\\site-packages\\keras\\engine\\training.py\", line 1146, in step_function\n      outputs = model.distribute_strategy.run(run_step, args=(data,))\n    File \"c:\\Users\\Bugi\\miniconda3\\envs\\modeling\\lib\\site-packages\\keras\\engine\\training.py\", line 1135, in run_step\n      outputs = model.train_step(data)\n    File \"c:\\Users\\Bugi\\miniconda3\\envs\\modeling\\lib\\site-packages\\keras\\engine\\training.py\", line 997, in train_step\n      self.optimizer.minimize(loss, self.trainable_variables, tape=tape)\n    File \"c:\\Users\\Bugi\\miniconda3\\envs\\modeling\\lib\\site-packages\\keras\\optimizers\\optimizer_v2\\optimizer_v2.py\", line 576, in minimize\n      grads_and_vars = self._compute_gradients(\n    File \"c:\\Users\\Bugi\\miniconda3\\envs\\modeling\\lib\\site-packages\\keras\\optimizers\\optimizer_v2\\optimizer_v2.py\", line 634, in _compute_gradients\n      grads_and_vars = self._get_gradients(\n    File \"c:\\Users\\Bugi\\miniconda3\\envs\\modeling\\lib\\site-packages\\keras\\optimizers\\optimizer_v2\\optimizer_v2.py\", line 510, in _get_gradients\n      grads = tape.gradient(loss, var_list, grad_loss)\nNode: 'gradient_tape/model/conv2d_10/Conv2D/Conv2DBackpropInput'\nNo algorithm worked!  Error messages:\n  Profiling failure on CUDNN engine 1#TC: RESOURCE_EXHAUSTED: Out of memory while trying to allocate 151096336 bytes.\n  Profiling failure on CUDNN engine 1: RESOURCE_EXHAUSTED: Out of memory while trying to allocate 151096336 bytes.\n  Profiling failure on CUDNN engine 2#TC: RESOURCE_EXHAUSTED: Out of memory while trying to allocate 289407744 bytes.\n  Profiling failure on CUDNN engine 2: RESOURCE_EXHAUSTED: Out of memory while trying to allocate 289407744 bytes.\n  Profiling failure on CUDNN engine 3#TC: RESOURCE_EXHAUSTED: Out of memory while trying to allocate 91448832 bytes.\n  Profiling failure on CUDNN engine 3: RESOURCE_EXHAUSTED: Out of memory while trying to allocate 91448832 bytes.\n  Profiling failure on CUDNN engine 0#TC: RESOURCE_EXHAUSTED: Out of memory while trying to allocate 16777216 bytes.\n  Profiling failure on CUDNN engine 0: RESOURCE_EXHAUSTED: Out of memory while trying to allocate 16777216 bytes.\n\t [[{{node gradient_tape/model/conv2d_10/Conv2D/Conv2DBackpropInput}}]] [Op:__inference_train_function_1632]"
     ]
    }
   ],
   "source": [
    "unet_custom.fit(trainset,\n",
    "                validation_data=valset,\n",
    "                epochs=10)"
   ]
  },
  {
   "cell_type": "code",
   "execution_count": 21,
   "metadata": {},
   "outputs": [
    {
     "name": "stdout",
     "output_type": "stream",
     "text": [
      "(32, 128, 128, 3)\n",
      "32\n",
      "(32, 128, 128, 3)\n",
      "32\n"
     ]
    },
    {
     "ename": "InvalidArgumentError",
     "evalue": "{{function_node __wrapped__IteratorGetNext_output_types_2_device_/job:localhost/replica:0/task:0/device:CPU:0}} jpeg::Uncompress failed. Invalid JPEG data or crop window.\n\t [[{{node DecodeJpeg}}]] [Op:IteratorGetNext]",
     "output_type": "error",
     "traceback": [
      "\u001b[1;31m---------------------------------------------------------------------------\u001b[0m",
      "\u001b[1;31mInvalidArgumentError\u001b[0m                      Traceback (most recent call last)",
      "Cell \u001b[1;32mIn[21], line 3\u001b[0m\n\u001b[0;32m      1\u001b[0m \u001b[38;5;28;01mimport\u001b[39;00m \u001b[38;5;21;01mmatplotlib\u001b[39;00m\u001b[38;5;21;01m.\u001b[39;00m\u001b[38;5;21;01mpyplot\u001b[39;00m \u001b[38;5;28;01mas\u001b[39;00m \u001b[38;5;21;01mplt\u001b[39;00m\n\u001b[1;32m----> 3\u001b[0m \u001b[38;5;28;01mfor\u001b[39;00m images, masks \u001b[38;5;129;01min\u001b[39;00m trainset\u001b[38;5;241m.\u001b[39mtake(\u001b[38;5;241m9\u001b[39m):\n\u001b[0;32m      4\u001b[0m     \u001b[38;5;28mprint\u001b[39m(images\u001b[38;5;241m.\u001b[39mshape)\n\u001b[0;32m      5\u001b[0m     \u001b[38;5;28mprint\u001b[39m(\u001b[38;5;28mlen\u001b[39m(images))\n",
      "File \u001b[1;32mc:\\Users\\Bugi\\miniconda3\\envs\\modeling\\lib\\site-packages\\tensorflow\\python\\data\\ops\\iterator_ops.py:766\u001b[0m, in \u001b[0;36mOwnedIterator.__next__\u001b[1;34m(self)\u001b[0m\n\u001b[0;32m    764\u001b[0m \u001b[38;5;28;01mdef\u001b[39;00m \u001b[38;5;21m__next__\u001b[39m(\u001b[38;5;28mself\u001b[39m):\n\u001b[0;32m    765\u001b[0m   \u001b[38;5;28;01mtry\u001b[39;00m:\n\u001b[1;32m--> 766\u001b[0m     \u001b[38;5;28;01mreturn\u001b[39;00m \u001b[38;5;28;43mself\u001b[39;49m\u001b[38;5;241;43m.\u001b[39;49m\u001b[43m_next_internal\u001b[49m\u001b[43m(\u001b[49m\u001b[43m)\u001b[49m\n\u001b[0;32m    767\u001b[0m   \u001b[38;5;28;01mexcept\u001b[39;00m errors\u001b[38;5;241m.\u001b[39mOutOfRangeError:\n\u001b[0;32m    768\u001b[0m     \u001b[38;5;28;01mraise\u001b[39;00m \u001b[38;5;167;01mStopIteration\u001b[39;00m\n",
      "File \u001b[1;32mc:\\Users\\Bugi\\miniconda3\\envs\\modeling\\lib\\site-packages\\tensorflow\\python\\data\\ops\\iterator_ops.py:749\u001b[0m, in \u001b[0;36mOwnedIterator._next_internal\u001b[1;34m(self)\u001b[0m\n\u001b[0;32m    746\u001b[0m \u001b[38;5;66;03m# TODO(b/77291417): This runs in sync mode as iterators use an error status\u001b[39;00m\n\u001b[0;32m    747\u001b[0m \u001b[38;5;66;03m# to communicate that there is no more data to iterate over.\u001b[39;00m\n\u001b[0;32m    748\u001b[0m \u001b[38;5;28;01mwith\u001b[39;00m context\u001b[38;5;241m.\u001b[39mexecution_mode(context\u001b[38;5;241m.\u001b[39mSYNC):\n\u001b[1;32m--> 749\u001b[0m   ret \u001b[38;5;241m=\u001b[39m \u001b[43mgen_dataset_ops\u001b[49m\u001b[38;5;241;43m.\u001b[39;49m\u001b[43miterator_get_next\u001b[49m\u001b[43m(\u001b[49m\n\u001b[0;32m    750\u001b[0m \u001b[43m      \u001b[49m\u001b[38;5;28;43mself\u001b[39;49m\u001b[38;5;241;43m.\u001b[39;49m\u001b[43m_iterator_resource\u001b[49m\u001b[43m,\u001b[49m\n\u001b[0;32m    751\u001b[0m \u001b[43m      \u001b[49m\u001b[43moutput_types\u001b[49m\u001b[38;5;241;43m=\u001b[39;49m\u001b[38;5;28;43mself\u001b[39;49m\u001b[38;5;241;43m.\u001b[39;49m\u001b[43m_flat_output_types\u001b[49m\u001b[43m,\u001b[49m\n\u001b[0;32m    752\u001b[0m \u001b[43m      \u001b[49m\u001b[43moutput_shapes\u001b[49m\u001b[38;5;241;43m=\u001b[39;49m\u001b[38;5;28;43mself\u001b[39;49m\u001b[38;5;241;43m.\u001b[39;49m\u001b[43m_flat_output_shapes\u001b[49m\u001b[43m)\u001b[49m\n\u001b[0;32m    754\u001b[0m   \u001b[38;5;28;01mtry\u001b[39;00m:\n\u001b[0;32m    755\u001b[0m     \u001b[38;5;66;03m# Fast path for the case `self._structure` is not a nested structure.\u001b[39;00m\n\u001b[0;32m    756\u001b[0m     \u001b[38;5;28;01mreturn\u001b[39;00m \u001b[38;5;28mself\u001b[39m\u001b[38;5;241m.\u001b[39m_element_spec\u001b[38;5;241m.\u001b[39m_from_compatible_tensor_list(ret)  \u001b[38;5;66;03m# pylint: disable=protected-access\u001b[39;00m\n",
      "File \u001b[1;32mc:\\Users\\Bugi\\miniconda3\\envs\\modeling\\lib\\site-packages\\tensorflow\\python\\ops\\gen_dataset_ops.py:3016\u001b[0m, in \u001b[0;36miterator_get_next\u001b[1;34m(iterator, output_types, output_shapes, name)\u001b[0m\n\u001b[0;32m   3014\u001b[0m   \u001b[38;5;28;01mreturn\u001b[39;00m _result\n\u001b[0;32m   3015\u001b[0m \u001b[38;5;28;01mexcept\u001b[39;00m _core\u001b[38;5;241m.\u001b[39m_NotOkStatusException \u001b[38;5;28;01mas\u001b[39;00m e:\n\u001b[1;32m-> 3016\u001b[0m   \u001b[43m_ops\u001b[49m\u001b[38;5;241;43m.\u001b[39;49m\u001b[43mraise_from_not_ok_status\u001b[49m\u001b[43m(\u001b[49m\u001b[43me\u001b[49m\u001b[43m,\u001b[49m\u001b[43m \u001b[49m\u001b[43mname\u001b[49m\u001b[43m)\u001b[49m\n\u001b[0;32m   3017\u001b[0m \u001b[38;5;28;01mexcept\u001b[39;00m _core\u001b[38;5;241m.\u001b[39m_FallbackException:\n\u001b[0;32m   3018\u001b[0m   \u001b[38;5;28;01mpass\u001b[39;00m\n",
      "File \u001b[1;32mc:\\Users\\Bugi\\miniconda3\\envs\\modeling\\lib\\site-packages\\tensorflow\\python\\framework\\ops.py:7209\u001b[0m, in \u001b[0;36mraise_from_not_ok_status\u001b[1;34m(e, name)\u001b[0m\n\u001b[0;32m   7207\u001b[0m \u001b[38;5;28;01mdef\u001b[39;00m \u001b[38;5;21mraise_from_not_ok_status\u001b[39m(e, name):\n\u001b[0;32m   7208\u001b[0m   e\u001b[38;5;241m.\u001b[39mmessage \u001b[38;5;241m+\u001b[39m\u001b[38;5;241m=\u001b[39m (\u001b[38;5;124m\"\u001b[39m\u001b[38;5;124m name: \u001b[39m\u001b[38;5;124m\"\u001b[39m \u001b[38;5;241m+\u001b[39m name \u001b[38;5;28;01mif\u001b[39;00m name \u001b[38;5;129;01mis\u001b[39;00m \u001b[38;5;129;01mnot\u001b[39;00m \u001b[38;5;28;01mNone\u001b[39;00m \u001b[38;5;28;01melse\u001b[39;00m \u001b[38;5;124m\"\u001b[39m\u001b[38;5;124m\"\u001b[39m)\n\u001b[1;32m-> 7209\u001b[0m   \u001b[38;5;28;01mraise\u001b[39;00m core\u001b[38;5;241m.\u001b[39m_status_to_exception(e) \u001b[38;5;28;01mfrom\u001b[39;00m \u001b[38;5;28;01mNone\u001b[39;00m\n",
      "\u001b[1;31mInvalidArgumentError\u001b[0m: {{function_node __wrapped__IteratorGetNext_output_types_2_device_/job:localhost/replica:0/task:0/device:CPU:0}} jpeg::Uncompress failed. Invalid JPEG data or crop window.\n\t [[{{node DecodeJpeg}}]] [Op:IteratorGetNext]"
     ]
    }
   ],
   "source": [
    "import matplotlib.pyplot as plt\n",
    "\n",
    "for images, masks in trainset.take(9):\n",
    "    print(images.shape)\n",
    "    print(len(images))\n",
    "    # for i in range(3):\n",
    "    #     plt.subplot(1, 3, i + 1)\n",
    "    #     plt.imshow(images[i])\n",
    "    #     plt.imshow(masks[i], alpha=0.5)\n",
    "    # plt.show()\n",
    "    # break"
   ]
  }
 ],
 "metadata": {
  "kernelspec": {
   "display_name": "modeling",
   "language": "python",
   "name": "python3"
  },
  "language_info": {
   "codemirror_mode": {
    "name": "ipython",
    "version": 3
   },
   "file_extension": ".py",
   "mimetype": "text/x-python",
   "name": "python",
   "nbconvert_exporter": "python",
   "pygments_lexer": "ipython3",
   "version": "3.10.14"
  }
 },
 "nbformat": 4,
 "nbformat_minor": 2
}
